Workbook

Sheet Resources
A1: Named Resource | B1: OQ | C1: Conductivity | D1: Hardness | E1: Heat Resistance | F1: Malleability | G1: Family
A2: Keth Iron | B2: 520 | C2: 220 | D2: 650 | E2: 480 | F2: 560 | G2: SA
A3: Asterion Frame Alloy | B3: 690 | C3: 260 | D3: 850 | E3: 610 | F3: 760 | G3: SA
A4: Bendrel Ridge Alloy | B4: 610 | C4: 150 | D4: 430 | E4: 330 | F4: 880 | G4: SA
A5: Red Mesa Conductive Slag | B5: 340 | C5: 610 | D5: 310 | E5: 720 | F5: 390 | G5: CM
A6: Veyrith Copper | B6: 820 | C6: 930 | D6: 260 | E6: 540 | F6: 620 | G6: CM
A7: Sorrel Vein Copper | B7: 560 | C7: 640 | D7: 210 | E7: 430 | F7: 760 | G7: CM
A8: Pale Ember Crystal | B8: 680 | C8: 520 | D8: 360 | E8: 880 | F8: 470 | G8: RC
A9: Thornwake Crystal | B9: 590 | C9: 910 | D9: 420 | E9: 210 | F9: 160 | G9: RC
A10: Glimmerfall Shard | B10: 800 | C10: 680 | D10: 300 | E10: 640 | F10: 210 | G10: RC
A12: Decision 010/021 locked prototype stats (1–1000). Blue = inputs you can tune.

Sheet Weights
A1: Recipe | B1: Property | C1: w1 | D1: slot1 | E1: stat1 | F1: w2 | G1: slot2 | H1: stat2 | I1: w3 | J1: slot3 | K1: stat3
A2: Basic Drill Head | B2: Extraction Rate | C2: 0.5 | D2: 1 | E2: Hardness | F2: 0.3 | G2: 2 | H2: Conductivity | I2: 0.2 | J2: 0 | K2: OQ
A3: Basic Drill Head | B3: Depth Access | C3: 0.5 | D3: 1 | E3: Hardness | F3: 0.3 | G3: 3 | H3: Heat Resistance | I3: 0.2 | J3: 0 | K3: OQ
A4: Basic Drill Head | B4: Wear Control | C4: 0.45 | D4: 3 | E4: Heat Resistance | F4: 0.35 | G4: 1 | H4: Malleability | I4: 0.2 | J4: 0 | K4: OQ
A5: Efficient Pump | B5: Recovery Efficiency | C5: 0.45 | D5: 1 | E5: Conductivity | F5: 0.35 | G5: 2 | H5: Malleability | I5: 0.2 | J5: 0 | K5: OQ
A6: Efficient Pump | B6: Clog Resistance | C6: 0.45 | D6: 2 | E6: Malleability | F6: 0.3 | G6: 2 | H6: Hardness | I6: 0.25 | J6: 0 | K6: OQ
A7: Efficient Pump | B7: Field Stability | C7: 0.45 | D7: 3 | E7: Heat Resistance | F7: 0.35 | G7: 1 | H7: Malleability | I7: 0.2 | J7: 0 | K7: OQ
A8: Reinforced Hull Plate | B8: Max Condition | C8: 0.45 | D8: 1 | E8: Hardness | F8: 0.3 | G8: 2 | H8: Malleability | I8: 0.25 | J8: 0 | K8: OQ
A9: Reinforced Hull Plate | B9: Damage Reduction | C9: 0.5 | D9: 1 | E9: Hardness | F9: 0.3 | G9: 3 | H9: Heat Resistance | I9: 0.2 | J9: 0 | K9: OQ
A10: Reinforced Hull Plate | B10: Repairability | C10: 0.45 | D10: 2 | E10: Malleability | F10: 0.35 | G10: 0 | H10: OQ | I10: 0.2 | J10: 1 | K10: Hardness
A11: Survey Scanner Module Mk I | B11: Survey Clarity | C11: 0.6 | D11: 1 | E11: Conductivity | F11: 0.25 | G11: 2 | H11: Conductivity | I11: 0.15 | J11: 0 | K11: OQ
A12: Survey Scanner Module Mk I | B12: Stat Hint Accuracy | C12: 0.5 | D12: 1 | E12: Conductivity | F12: 0.3 | G12: 2 | H12: Heat Resistance | I12: 0.2 | J12: 0 | K12: OQ
A13: Survey Scanner Module Mk I | B13: Signal Range | C13: 0.55 | D13: 1 | E13: Conductivity | F13: 0.25 | G13: 2 | H13: Heat Resistance | I13: 0.2 | J13: 0 | K13: OQ
... A16: Field Repair Kit | B16: Field Reliability | C16: 0.45 | D16: 3 | E16: Heat Resistance | F16: 0.35 | G16: 2 | H16: Heat Resistance | I16: 0.2 | J16: 0 | K16: OQ
A18: slot: 1/2/3 = recipe slot; 0 = average OQ of all three resources. Blue = tunable inputs.
A19: Weights include LOCKED Decisions 016 A/B and 021-A. Blue = tunable inputs.

Sheet Craft Model
A1: Recipe | B1: Slot 1 | C1: Slot 2 | D1: Slot 3 | E1: Avg OQ | F1: Prop 1 | G1: Score | H1: Band | I1: Prop 2 | J1: Score | K1: Band | L1: Prop 3 | M1: Score | N1: Band | O1: Best line +3 pts | P1: Band
A2: Basic Drill Head | B2: Keth Iron | C2: Red Mesa Conductive Slag | D2: Pale Ember Crystal | E2: =AVERAGE(INDEX(Resources!$B$2:$F$10,MATCH($B2,Resources!$A$2:$A$10,0),1),INDEX(Resources!$B$2:$F$10,MATCH($C2,Resources!$A$2:$A$10,0),1),INDEX(Resources!$B$2:$F$10,MATCH($D2,Resources!$A$2:$A$10,0),1)) -> 513.33333 | F2: Extraction Rate | G2: =(Weights!$C$2*IF(Weights!$D$2=0,$E2,INDEX(Resources!$B$2:$F$10,MATCH(CHOOSE(Weights!$D$2,$B2,$C2,$D2),Resources!$A$2:$A$10,0),MATCH(Weights!$E$2,Resources!$B$1:$F$1,0)))+Weights!$F$2*IF(Weights!$G$2=0,$E2,INDEX(Resources!$B$2:$F$10,MATCH(CHOOSE(Weights!$G$2,$B2,$C2,$D2),Resources!$A$2:$A$10,0),MATCH(Weights!$H$2,Resources!$B$1:$F$1,0)))+Weights!$I$2*IF(Weights!$J$2=0,$E2,INDEX(Resources!$B$2:$F$10,MATCH(CHOOSE(Weights!$J$2,$B2,$C2,$D2),Resources!$A$2:$A$10,0),MATCH(Weights!$K$2,Resources!$B$1:$F$1,0))))/10 -> 61.066667 | H2: =IF(G2<40,"Poor",IF(G2<55,"Basic",IF(G2<70,"Solid",IF(G2<85,"Strong",IF(G2<95,"Excellent","Exceptional"))))) -> Solid | I2: Depth Access | J2: =(Weights!$C$3*IF(Weights!$D$3=0,$E2,INDEX(Resources!$B$2:$F$10,MATCH(CHOOSE(Weights!$D$3,$B2,$C2,$D2),Resources!$A$2:$A$10,0),MATCH(Weights!$E$3,Resources!$B$1:$F$1,0)))+Weights!$F$3*IF(Weights!$G$3=0,$E2,INDEX(Resources!$B$2:$F$10,MATCH(CHOOSE(Weights!$G$3,$B2,$C2,$D2),Resources!$A$2:$A$10,0),MATCH(Weights!$H$3,Resources!$B$1:$F$1,0)))+Weights!$I$3*IF(Weights!$J$3=0,$E2,INDEX(Resources!$B$2:$F$10,MATCH(CHOOSE(Weights!$J$3,$B2,$C2,$D2),Resources!$A$2:$A$10,0),MATCH(Weights!$K$3,Resources!$B$1:$F$1,0))))/10 -> 69.166667 | K2: =IF(J2<40,"Poor",IF(J2<55,"Basic",IF(J2<70,"Solid",IF(J2<85,"Strong",IF(J2<95,"Excellent","Exceptional"))))) -> Solid | L2: Wear Control | M2: =(Weights!$C$4*IF(Weights!$D$4=0,$E2,INDEX(Resources!$B$2:$F$10,MATCH(CHOOSE(Weights!$D$4,$B2,$C2,$D2),Resources!$A$2:$A$10,0),MATCH(Weights!$E$4,Resources!$B$1:$F$1,0)))+Weights!$F$4*IF(Weights!$G$4=0,$E2,INDEX(Resources!$B$2:$F$10,MATCH(CHOOSE(Weights!$G$4,$B2,$C2,$D2),Resources!$A$2:$A$10,0),MATCH(Weights!$H$4,Resources!$B$1:$F$1,0)))+Weights!$I$4*IF(Weights!$J$4=0,$E2,INDEX(Resources!$B$2:$F$10,MATCH(CHOOSE(Weights!$J$4,$B2,$C2,$D2),Resources!$A$2:$A$10,0),MATCH(Weights!$K$4,Resources!$B$1:$F$1,0))))/10 -> 69.466667 | N2: =IF(M2<40,"Poor",IF(M2<55,"Basic",IF(M2<70,"Solid",IF(M2<85,"Strong",IF(M2<95,"Excellent","Exceptional"))))) -> Solid | O2: =MIN(100,MAX(G2,J2,M2)*(1+0.05*3)) -> 79.886667 | P2: =IF(O2<40,"Poor",IF(O2<55,"Basic",IF(O2<70,"Solid",IF(O2<85,"Strong",IF(O2<95,"Excellent","Exceptional"))))) -> Strong
A3: Basic Drill Head | B3: Keth Iron | C3: Red Mesa Conductive Slag | D3: Thornwake Crystal | E3: =AVERAGE(INDEX(Resources!$B$2:$F$10,MATCH($B3,Resources!$A$2:$A$10,0),1),INDEX(Resources!$B$2:$F$10,MATCH($C3,Resources!$A$2:$A$10,0),1),INDEX(Resources!$B$2:$F$10,MATCH($D3,Resources!$A$2:$A$10,0),1)) -> 483.33333 | F3: Extraction Rate | G3: =(Weights!$C$2*IF(Weights!$D$2=0,$E3,INDEX(Resources!$B$2:$F$10,MATCH(CHOOSE(Weights!$D$2,$B3,$C3,$D3),Resources!$A$2:$A$10,0),MATCH(Weights!$E$2,Resources!$B$1:$F$1,0)))+Weights!$F$2*IF(Weights!$G$2=0,$E3,INDEX(Resources!$B$2:$F$10,MATCH(CHOOSE(Weights!$G$2,$B3,$C3,$D3),Resources!$A$2:$A$10,0),MATCH(Weights!$H$2,Resources!$B$1:$F$1,0)))+Weights!$I$2*IF(Weights!$J$2=0,$E3,INDEX(Resources!$B$2:$F$10,MATCH(CHOOSE(Weights!$J$2,$B3,$C3,$D3),Resources!$A$2:$A$10,0),MATCH(Weights!$K$2,Resources!$B$1:$F$1,0))))/10 -> 60.466667 | H3: =IF(G3<40,"Poor",IF(G3<55,"Basic",IF(G3<70,"Solid",IF(G3<85,"Strong",IF(G3<95,"Excellent","Exceptional"))))) -> Solid | I3: Depth Access | J3: =(Weights!$C$3*IF(Weights!$D$3=0,$E3,INDEX(Resources!$B$2:$F$10,MATCH(CHOOSE(Weights!$D$3,$B3,$C3,$D3),Resources!$A$2:$A$10,0),MATCH(Weights!$E$3,Resources!$B$1:$F$1,0)))+Weights!$F$3*IF(Weights!$G$3=0,$E3,INDEX(Resources!$B$2:$F$10,MATCH(CHOOSE(Weights!$G$3,$B3,$C3,$D3),Resources!$A$2:$A$10,0),MATCH(Weights!$H$3,Resources!$B$1:$F$1,0)))+Weights!$I$3*IF(Weights!$J$3=0,$E3,INDEX(Resources!$B$2:$F$10,MATCH(CHOOSE(Weights!$J$3,$B3,$C3,$D3),Resources!$A$2:$A$10,0),MATCH(Weights!$K$3,Resources!$B$1:$F$1,0))))/10 -> 48.466667 | K3: =IF(J3<40,"Poor",IF(J3<55,"Basic",IF(J3<70,"Solid",IF(J3<85,"Strong",IF(J3<95,"Excellent","Exceptional"))))) -> Basic | L3: Wear Control | M3: =(Weights!$C$4*IF(Weights!$D$4=0,$E3,INDEX(Resources!$B$2:$F$10,MATCH(CHOOSE(Weights!$D$4,$B3,$C3,$D3),Resources!$A$2:$A$10,0),MATCH(Weights!$E$4,Resources!$B$1:$F$1,0)))+Weights!$F$4*IF(Weights!$G$4=0,$E3,INDEX(Resources!$B$2:$F$10,MATCH(CHOOSE(Weights!$G$4,$B3,$C3,$D3),Resources!$A$2:$A$10,0),MATCH(Weights!$H$4,Resources!$B$1:$F$1,0)))+Weights!$I$4*IF(Weights!$J$4=0,$E3,INDEX(Resources!$B$2:$F$10,MATCH(CHOOSE(Weights!$J$4,$B3,$C3,$D3),Resources!$A$2:$A$10,0),MATCH(Weights!$K$4,Resources!$B$1:$F$1,0))))/10 -> 38.716667 | N3: =IF(M3<40,"Poor",IF(M3<55,"Basic",IF(M3<70,"Solid",IF(M3<85,"Strong",IF(M3<95,"Excellent","Exceptional"))))) -> Poor | O3: =MIN(100,MAX(G3,J3,M3)*(1+0.05*3)) -> 69.536667 | P3: =IF(O3<40,"Poor",IF(O3<55,"Basic",IF(O3<70,"Solid",IF(O3<85,"Strong",IF(O3<95,"Excellent","Exceptional"))))) -> Solid
A4: Basic Drill Head | B4: Keth Iron | C4: Red Mesa Conductive Slag | D4: Glimmerfall Shard | E4: =AVERAGE(INDEX(Resources!$B$2:$F$10,MATCH($B4,Resources!$A$2:$A$10,0),1),INDEX(Resources!$B$2:$F$10,MATCH($C4,Resources!$A$2:$A$10,0),1),INDEX(Resources!$B$2:$F$10,MATCH($D4,Resources!$A$2:$A$10,0),1)) -> 553.33333 | F4: Extraction Rate | G4: =(Weights!$C$2*IF(Weights!$D$2=0,$E4,INDEX(Resources!$B$2:$F$10,MATCH(CHOOSE(Weights!$D$2,$B4,$C4,$D4),Resources!$A$2:$A$10,0),MATCH(Weights!$E$2,Resources!$B$1:$F$1,0)))+Weights!$F$2*IF(Weights!$G$2=0,$E4,INDEX(Resources!$B$2:$F$10,MATCH(CHOOSE(Weights!$G$2,$B4,$C4,$D4),Resources!$A$2:$A$10,0),MATCH(Weights!$H$2,Resources!$B$1:$F$1,0)))+Weights!$I$2*IF(Weights!$J$2=0,$E4,INDEX(Resources!$B$2:$F$10,MATCH(CHOOSE(Weights!$J$2,$B4,$C4,$D4),Resources!$A$2:$A$10,0),MATCH(Weights!$K$2,Resources!$B$1:$F$1,0))))/10 -> 61.866667 | H4: =IF(G4<40,"Poor",IF(G4<55,"Basic",IF(G4<70,"Solid",IF(G4<85,"Strong",IF(G4<95,"Excellent","Exceptional"))))) -> Solid | I4: Depth Access | J4: =(Weights!$C$3*IF(Weights!$D$3=0,$E4,INDEX(Resources!$B$2:$F$10,MATCH(CHOOSE(Weights!$D$3,$B4,$C4,$D4),Resources!$A$2:$A$10,0),MATCH(Weights!$E$3,Resources!$B$1:$F$1,0)))+Weights!$F$3*IF(Weights!$G$3=0,$E4,INDEX(Resources!$B$2:$F$10,MATCH(CHOOSE(Weights!$G$3,$B4,$C4,$D4),Resources!$A$2:$A$10,0),MATCH(Weights!$H$3,Resources!$B$1:$F$1,0)))+Weights!$I$3*IF(Weights!$J$3=0,$E4,INDEX(Resources!$B$2:$F$10,MATCH(CHOOSE(Weights!$J$3,$B4,$C4,$D4),Resources!$A$2:$A$10,0),MATCH(Weights!$K$3,Resources!$B$1:$F$1,0))))/10 -> 62.766667 | K4: =IF(J4<40,"Poor",IF(J4<55,"Basic",IF(J4<70,"Solid",IF(J4<85,"Strong",IF(J4<95,"Excellent","Exceptional"))))) -> Solid | L4: Wear Control | M4: =(Weights!$C$4*IF(Weights!$D$4=0,$E4,INDEX(Resources!$B$2:$F$10,MATCH(CHOOSE(Weights!$D$4,$B4,$C4,$D4),Resources!$A$2:$A$10,0),MATCH(Weights!$E$4,Resources!$B$1:$F$1,0)))+Weights!$F$4*IF(Weights!$G$4=0,$E4,INDEX(Resources!$B$2:$F$10,MATCH(CHOOSE(Weights!$G$4,$B4,$C4,$D4),Resources!$A$2:$A$10,0),MATCH(Weights!$H$4,Resources!$B$1:$F$1,0)))+Weights!$I$4*IF(Weights!$J$4=0,$E4,INDEX(Resources!$B$2:$F$10,MATCH(CHOOSE(Weights!$J$4,$B4,$C4,$D4),Resources!$A$2:$A$10,0),MATCH(Weights!$K$4,Resources!$B$1:$F$1,0))))/10 -> 59.466667 | N4: =IF(M4<40,"Poor",IF(M4<55,"Basic",IF(M4<70,"Solid",IF(M4<85,"Strong",IF(M4<95,"Excellent","Exceptional"))))) -> Solid | O4: =MIN(100,MAX(G4,J4,M4)*(1+0.05*3)) -> 72.181667 | P4: =IF(O4<40,"Poor",IF(O4<55,"Basic",IF(O4<70,"Solid",IF(O4<85,"Strong",IF(O4<95,"Excellent","Exceptional"))))) -> Strong
A5: Basic Drill Head | B5: Keth Iron | C5: Veyrith Copper | D5: Pale Ember Crystal | E5: =AVERAGE(INDEX(Resources!$B$2:$F$10,MATCH($B5,Resources!$A$2:$A$10,0),1),INDEX(Resources!$B$2:$F$10,MATCH($C5,Resources!$A$2:$A$10,0),1),INDEX(Resources!$B$2:$F$10,MATCH($D5,Resources!$A$2:$A$10,0),1)) -> 673.33333 | F5: Extraction Rate | G5: =(Weights!$C$2*IF(Weights!$D$2=0,$E5,INDEX(Resources!$B$2:$F$10,MATCH(CHOOSE(Weights!$D$2,$B5,$C5,$D5),Resources!$A$2:$A$10,0),MATCH(Weights!$E$2,Resources!$B$1:$F$1,0)))+Weights!$F$2*IF(Weights!$G$2=0,$E5,INDEX(Resources!$B$2:$F$10,MATCH(CHOOSE(Weights!$G$2,$B5,$C5,$D5),Resources!$A$2:$A$10,0),MATCH(Weights!$H$2,Resources!$B$1:$F$1,0)))+Weights!$I$2*IF(Weights!$J$2=0,$E5,INDEX(Resources!$B$2:$F$10,MATCH(CHOOSE(Weights!$J$2,$B5,$C5,$D5),Resources!$A$2:$A$10,0),MATCH(Weights!$K$2,Resources!$B$1:$F$1,0))))/10 -> 73.866667 | H5: =IF(G5<40,"Poor",IF(G5<55,"Basic",IF(G5<70,"Solid",IF(G5<85,"Strong",IF(G5<95,"Excellent","Exceptional"))))) -> Strong | I5: Depth Access | J5: =(Weights!$C$3*IF(Weights!$D$3=0,$E5,INDEX(Resources!$B$2:$F$10,MATCH(CHOOSE(Weights!$D$3,$B5,$C5,$D5),Resources!$A$2:$A$10,0),MATCH(Weights!$E$3,Resources!$B$1:$F$1,0)))+Weights!$F$3*IF(Weights!$G$3=0,$E5,INDEX(Resources!$B$2:$F$10,MATCH(CHOOSE(Weights!$G$3,$B5,$C5,$D5),Resources!$A$2:$A$10,0),MATCH(Weights!$H$3,Resources!$B$1:$F$1,0)))+Weights!$I$3*IF(Weights!$J$3=0,$E5,INDEX(Resources!$B$2:$F$10,MATCH(CHOOSE(Weights!$J$3,$B5,$C5,$D5),Resources!$A$2:$A$10,0),MATCH(Weights!$K$3,Resources!$B$1:$F$1,0))))/10 -> 72.366667 | K5: =IF(J5<40,"Poor",IF(J5<55,"Basic",IF(J5<70,"Solid",IF(J5<85,"Strong",IF(J5<95,"Excellent","Exceptional"))))) -> Strong | L5: Wear Control | M5: =(Weights!$C$4*IF(Weights!$D$4=0,$E5,INDEX(Resources!$B$2:$F$10,MATCH(CHOOSE(Weights!$D$4,$B5,$C5,$D5),Resources!$A$2:$A$10,0),MATCH(Weights!$E$4,Resources!$B$1:$F$1,0)))+Weights!$F$4*IF(Weights!$G$4=0,$E5,INDEX(Resources!$B$2:$F$10,MATCH(CHOOSE(Weights!$G$4,$B5,$C5,$D5),Resources!$A$2:$A$10,0),MATCH(Weights!$H$4,Resources!$B$1:$F$1,0)))+Weights!$I$4*IF(Weights!$J$4=0,$E5,INDEX(Resources!$B$2:$F$10,MATCH(CHOOSE(Weights!$J$4,$B5,$C5,$D5),Resources!$A$2:$A$10,0),MATCH(Weights!$K$4,Resources!$B$1:$F$1,0))))/10 -> 72.666667 | N5: =IF(M5<40,"Poor",IF(M5<55,"Basic",IF(M5<70,"Solid",IF(M5<85,"Strong",IF(M5<95,"Excellent","Exceptional"))))) -> Strong | O5: =MIN(100,MAX(G5,J5,M5)*(1+0.05*3)) -> 84.946667 | P5: =IF(O5<40,"Poor",IF(O5<55,"Basic",IF(O5<70,"Solid",IF(O5<85,"Strong",IF(O5<95,"Excellent","Exceptional"))))) -> Strong
A6: Basic Drill Head | B6: Keth Iron | C6: Veyrith Copper | D6: Thornwake Crystal | E6: =AVERAGE(INDEX(Resources!$B$2:$F$10,MATCH($B6,Resources!$A$2:$A$10,0),1),INDEX(Resources!$B$2:$F$10,MATCH($C6,Resources!$A$2:$A$10,0),1),INDEX(Resources!$B$2:$F$10,MATCH($D6,Resources!$A$2:$A$10,0),1)) -> 643.33333 | F6: Extraction Rate | G6: =(Weights!$C$2*IF(Weights!$D$2=0,$E6,INDEX(Resources!$B$2:$F$10,MATCH(CHOOSE(Weights!$D$2,$B6,$C6,$D6),Resources!$A$2:$A$10,0),MATCH(Weights!$E$2,Resources!$B$1:$F$1,0)))+Weights!$F$2*IF(Weights!$G$2=0,$E6,INDEX(Resources!$B$2:$F$10,MATCH(CHOOSE(Weights!$G$2,$B6,$C6,$D6),Resources!$A$2:$A$10,0),MATCH(Weights!$H$2,Resources!$B$1:$F$1,0)))+Weights!$I$2*IF(Weights!$J$2=0,$E6,INDEX(Resources!$B$2:$F$10,MATCH(CHOOSE(Weights!$J$2,$B6,$C6,$D6),Resources!$A$2:$A$10,0),MATCH(Weights!$K$2,Resources!$B$1:$F$1,0))))/10 -> 73.266667 | H6: =IF(G6<40,"Poor",IF(G6<55,"Basic",IF(G6<70,"Solid",IF(G6<85,"Strong",IF(G6<95,"Excellent","Exceptional"))))) -> Strong | I6: Depth Access | J6: =(Weights!$C$3*IF(Weights!$D$3=0,$E6,INDEX(Resources!$B$2:$F$10,MATCH(CHOOSE(Weights!$D$3,$B6,$C6,$D6),Resources!$A$2:$A$10,0),MATCH(Weights!$E$3,Resources!$B$1:$F$1,0)))+Weights!$F$3*IF(Weights!$G$3=0,$E6,INDEX(Resources!$B$2:$F$10,MATCH(CHOOSE(Weights!$G$3,$B6,$C6,$D6),Resources!$A$2:$A$10,0),MATCH(Weights!$H$3,Resources!$B$1:$F$1,0)))+Weights!$I$3*IF(Weights!$J$3=0,$E6,INDEX(Resources!$B$2:$F$10,MATCH(CHOOSE(Weights!$J$3,$B6,$C6,$D6),Resources!$A$2:$A$10,0),MATCH(Weights!$K$3,Resources!$B$1:$F$1,0))))/10 -> 51.666667 | K6: =IF(J6<40,"Poor",IF(J6<55,"Basic",IF(J6<70,"Solid",IF(J6<85,"Strong",IF(J6<95,"Excellent","Exceptional"))))) -> Basic | L6: Wear Control | M6: =(Weights!$C$4*IF(Weights!$D$4=0,$E6,INDEX(Resources!$B$2:$F$10,MATCH(CHOOSE(Weights!$D$4,$B6,$C6,$D6),Resources!$A$2:$A$10,0),MATCH(Weights!$E$4,Resources!$B$1:$F$1,0)))+Weights!$F$4*IF(Weights!$G$4=0,$E6,INDEX(Resources!$B$2:$F$10,MATCH(CHOOSE(Weights!$G$4,$B6,$C6,$D6),Resources!$A$2:$A$10,0),MATCH(Weights!$H$4,Resources!$B$1:$F$1,0)))+Weights!$I$4*IF(Weights!$J$4=0,$E6,INDEX(Resources!$B$2:$F$10,MATCH(CHOOSE(Weights!$J$4,$B6,$C6,$D6),Resources!$A$2:$A$10,0),MATCH(Weights!$K$4,Resources!$B$1:$F$1,0))))/10 -> 41.916667 | N6: =IF(M6<40,"Poor",IF(M6<55,"Basic",IF(M6<70,"Solid",IF(M6<85,"Strong",IF(M6<95,"Excellent","Exceptional"))))) -> Basic | O6: =MIN(100,MAX(G6,J6,M6)*(1+0.05*3)) -> 84.256667 | P6: =IF(O6<40,"Poor",IF(O6<55,"Basic",IF(O6<70,"Solid",IF(O6<85,"Strong",IF(O6<95,"Excellent","Exceptional"))))) -> Strong
A7: Basic Drill Head | B7: Keth Iron | C7: Veyrith Copper | D7: Glimmerfall Shard | E7: =AVERAGE(INDEX(Resources!$B$2:$F$10,MATCH($B7,Resources!$A$2:$A$10,0),1),INDEX(Resources!$B$2:$F$10,MATCH($C7,Resources!$A$2:$A$10,0),1),INDEX(Resources!$B$2:$F$10,MATCH($D7,Resources!$A$2:$A$10,0),1)) -> 713.33333 | F7: Extraction Rate | G7: =(Weights!$C$2*IF(Weights!$D$2=0,$E7,INDEX(Resources!$B$2:$F$10,MATCH(CHOOSE(Weights!$D$2,$B7,$C7,$D7),Resources!$A$2:$A$10,0),MATCH(Weights!$E$2,Resources!$B$1:$F$1,0)))+Weights!$F$2*IF(Weights!$G$2=0,$E7,INDEX(Resources!$B$2:$F$10,MATCH(CHOOSE(Weights!$G$2,$B7,$C7,$D7),Resources!$A$2:$A$10,0),MATCH(Weights!$H$2,Resources!$B$1:$F$1,0)))+Weights!$I$2*IF(Weights!$J$2=0,$E7,INDEX(Resources!$B$2:$F$10,MATCH(CHOOSE(Weights!$J$2,$B7,$C7,$D7),Resources!$A$2:$A$10,0),MATCH(Weights!$K$2,Resources!$B$1:$F$1,0))))/10 -> 74.666667 | H7: =IF(G7<40,"Poor",IF(G7<55,"Basic",IF(G7<70,"Solid",IF(G7<85,"Strong",IF(G7<95,"Excellent","Exceptional"))))) -> Strong | I7: Depth Access | J7: =(Weights!$C$3*IF(Weights!$D$3=0,$E7,INDEX(Resources!$B$2:$F$10,MATCH(CHOOSE(Weights!$D$3,$B7,$C7,$D7),Resources!$A$2:$A$10,0),MATCH(Weights!$E$3,Resources!$B$1:$F$1,0)))+Weights!$F$3*IF(Weights!$G$3=0,$E7,INDEX(Resources!$B$2:$F$10,MATCH(CHOOSE(Weights!$G$3,$B7,$C7,$D7),Resources!$A$2:$A$10,0),MATCH(Weights!$H$3,Resources!$B$1:$F$1,0)))+Weights!$I$3*IF(Weights!$J$3=0,$E7,INDEX(Resources!$B$2:$F$10,MATCH(CHOOSE(Weights!$J$3,$B7,$C7,$D7),Resources!$A$2:$A$10,0),MATCH(Weights!$K$3,Resources!$B$1:$F$1,0))))/10 -> 65.966667 | K7: =IF(J7<40,"Poor",IF(J7<55,"Basic",IF(J7<70,"Solid",IF(J7<85,"Strong",IF(J7<95,"Excellent","Exceptional"))))) -> Solid | L7: Wear Control | M7: =(Weights!$C$4*IF(Weights!$D$4=0,$E7,INDEX(Resources!$B$2:$F$10,MATCH(CHOOSE(Weights!$D$4,$B7,$C7,$D7),Resources!$A$2:$A$10,0),MATCH(Weights!$E$4,Resources!$B$1:$F$1,0)))+Weights!$F$4*IF(Weights!$G$4=0,$E7,INDEX(Resources!$B$2:$F$10,MATCH(CHOOSE(Weights!$G$4,$B7,$C7,$D7),Resources!$A$2:$A$10,0),MATCH(Weights!$H$4,Resources!$B$1:$F$1,0)))+Weights!$I$4*IF(Weights!$J$4=0,$E7,INDEX(Resources!$B$2:$F$10,MATCH(CHOOSE(Weights!$J$4,$B7,$C7,$D7),Resources!$A$2:$A$10,0),MATCH(Weights!$K$4,Resources!$B$1:$F$1,0))))/10 -> 62.666667 | N7: =IF(M7<40,"Poor",IF(M7<55,"Basic",IF(M7<70,"Solid",IF(M7<85,"Strong",IF(M7<95,"Excellent","Exceptional"))))) -> Solid | O7: =MIN(100,MAX(G7,J7,M7)*(1+0.05*3)) -> 85.866667 | P7: =IF(O7<40,"Poor",IF(O7<55,"Basic",IF(O7<70,"Solid",IF(O7<85,"Strong",IF(O7<95,"Excellent","Exceptional"))))) -> Excellent
A8: Basic Drill Head | B8: Keth Iron | C8: Sorrel Vein Copper | D8: Pale Ember Crystal | E8: =AVERAGE(INDEX(Resources!$B$2:$F$10,MATCH($B8,Resources!$A$2:$A$10,0),1),INDEX(Resources!$B$2:$F$10,MATCH($C8,Resources!$A$2:$A$10,0),1),INDEX(Resources!$B$2:$F$10,MATCH($D8,Resources!$A$2:$A$10,0),1)) -> 586.66667 | F8: Extraction Rate | G8: =(Weights!$C$2*IF(Weights!$D$2=0,$E8,INDEX(Resources!$B$2:$F$10,MATCH(CHOOSE(Weights!$D$2,$B8,$C8,$D8),Resources!$A$2:$A$10,0),MATCH(Weights!$E$2,Resources!$B$1:$F$1,0)))+Weights!$F$2*IF(Weights!$G$2=0,$E8,INDEX(Resources!$B$2:$F$10,MATCH(CHOOSE(Weights!$G$2,$B8,$C8,$D8),Resources!$A$2:$A$10,0),MATCH(Weights!$H$2,Resources!$B$1:$F$1,0)))+Weights!$I$2*IF(Weights!$J$2=0,$E8,INDEX(Resources!$B$2:$F$10,MATCH(CHOOSE(Weights!$J$2,$B8,$C8,$D8),Resources!$A$2:$A$10,0),MATCH(Weights!$K$2,Resources!$B$1:$F$1,0))))/10 -> 63.433333 | H8: =IF(G8<40,"Poor",IF(G8<55,"Basic",IF(G8<70,"Solid",IF(G8<85,"Strong",IF(G8<95,"Excellent","Exceptional"))))) -> Solid | I8: Depth Access | J8: =(Weights!$C$3*IF(Weights!$D$3=0,$E8,INDEX(Resources!$B$2:$F$10,MATCH(CHOOSE(Weights!$D$3,$B8,$C8,$D8),Resources!$A$2:$A$10,0),MATCH(Weights!$E$3,Resources!$B$1:$F$1,0)))+Weights!$F$3*IF(Weights!$G$3=0,$E8,INDEX(Resources!$B$2:$F$10,MATCH(CHOOSE(Weights!$G$3,$B8,$C8,$D8),Resources!$A$2:$A$10,0),MATCH(Weights!$H$3,Resources!$B$1:$F$1,0)))+Weights!$I$3*IF(Weights!$J$3=0,$E8,INDEX(Resources!$B$2:$F$10,MATCH(CHOOSE(Weights!$J$3,$B8,$C8,$D8),Resources!$A$2:$A$10,0),MATCH(Weights!$K$3,Resources!$B$1:$F$1,0))))/10 -> 70.633333 | K8: =IF(J8<40,"Poor",IF(J8<55,"Basic",IF(J8<70,"Solid",IF(J8<85,"Strong",IF(J8<95,"Excellent","Exceptional"))))) -> Strong | L8: Wear Control | M8: =(Weights!$C$4*IF(Weights!$D$4=0,$E8,INDEX(Resources!$B$2:$F$10,MATCH(CHOOSE(Weights!$D$4,$B8,$C8,$D8),Resources!$A$2:$A$10,0),MATCH(Weights!$E$4,Resources!$B$1:$F$1,0)))+Weights!$F$4*IF(Weights!$G$4=0,$E8,INDEX(Resources!$B$2:$F$10,MATCH(CHOOSE(Weights!$G$4,$B8,$C8,$D8),Resources!$A$2:$A$10,0),MATCH(Weights!$H$4,Resources!$B$1:$F$1,0)))+Weights!$I$4*IF(Weights!$J$4=0,$E8,INDEX(Resources!$B$2:$F$10,MATCH(CHOOSE(Weights!$J$4,$B8,$C8,$D8),Resources!$A$2:$A$10,0),MATCH(Weights!$K$4,Resources!$B$1:$F$1,0))))/10 -> 70.933333 | N8: =IF(M8<40,"Poor",IF(M8<55,"Basic",IF(M8<70,"Solid",IF(M8<85,"Strong",IF(M8<95,"Excellent","Exceptional"))))) -> Strong | O8: =MIN(100,MAX(G8,J8,M8)*(1+0.05*3)) -> 81.573333 | P8: =IF(O8<40,"Poor",IF(O8<55,"Basic",IF(O8<70,"Solid",IF(O8<85,"Strong",IF(O8<95,"Excellent","Exceptional"))))) -> Strong
A9: Basic Drill Head | B9: Keth Iron | C9: Sorrel Vein Copper | D9: Thornwake Crystal | E9: =AVERAGE(INDEX(Resources!$B$2:$F$10,MATCH($B9,Resources!$A$2:$A$10,0),1),INDEX(Resources!$B$2:$F$10,MATCH($C9,Resources!$A$2:$A$10,0),1),INDEX(Resources!$B$2:$F$10,MATCH($D9,Resources!$A$2:$A$10,0),1)) -> 556.66667 | F9: Extraction Rate | G9: =(Weights!$C$2*IF(Weights!$D$2=0,$E9,INDEX(Resources!$B$2:$F$10,MATCH(CHOOSE(Weights!$D$2,$B9,$C9,$D9),Resources!$A$2:$A$10,0),MATCH(Weights!$E$2,Resources!$B$1:$F$1,0)))+Weights!$F$2*IF(Weights!$G$2=0,$E9,INDEX(Resources!$B$2:$F$10,MATCH(CHOOSE(Weights!$G$2,$B9,$C9,$D9),Resources!$A$2:$A$10,0),MATCH(Weights!$H$2,Resources!$B$1:$F$1,0)))+Weights!$I$2*IF(Weights!$J$2=0,$E9,INDEX(Resources!$B$2:$F$10,MATCH(CHOOSE(Weights!$J$2,$B9,$C9,$D9),Resources!$A$2:$A$10,0),MATCH(Weights!$K$2,Resources!$B$1:$F$1,0))))/10 -> 62.833333 | H9: =IF(G9<40,"Poor",IF(G9<55,"Basic",IF(G9<70,"Solid",IF(G9<85,"Strong",IF(G9<95,"Excellent","Exceptional"))))) -> Solid | I9: Depth Access | J9: =(Weights!$C$3*IF(Weights!$D$3=0,$E9,INDEX(Resources!$B$2:$F$10,MATCH(CHOOSE(Weights!$D$3,$B9,$C9,$D9),Resources!$A$2:$A$10,0),MATCH(Weights!$E$3,Resources!$B$1:$F$1,0)))+Weights!$F$3*IF(Weights!$G$3=0,$E9,INDEX(Resources!$B$2:$F$10,MATCH(CHOOSE(Weights!$G$3,$B9,$C9,$D9),Resources!$A$2:$A$10,0),MATCH(Weights!$H$3,Resources!$B$1:$F$1,0)))+Weights!$I$3*IF(Weights!$J$3=0,$E9,INDEX(Resources!$B$2:$F$10,MATCH(CHOOSE(Weights!$J$3,$B9,$C9,$D9),Resources!$A$2:$A$10,0),MATCH(Weights!$K$3,Resources!$B$1:$F$1,0))))/10 -> 49.933333 | K9: =IF(J9<40,"Poor",IF(J9<55,"Basic",IF(J9<70,"Solid",IF(J9<85,"Strong",IF(J9<95,"Excellent","Exceptional"))))) -> Basic | L9: Wear Control | M9: =(Weights!$C$4*IF(Weights!$D$4=0,$E9,INDEX(Resources!$B$2:$F$10,MATCH(CHOOSE(Weights!$D$4,$B9,$C9,$D9),Resources!$A$2:$A$10,0),MATCH(Weights!$E$4,Resources!$B$1:$F$1,0)))+Weights!$F$4*IF(Weights!$G$4=0,$E9,INDEX(Resources!$B$2:$F$10,MATCH(CHOOSE(Weights!$G$4,$B9,$C9,$D9),Resources!$A$2:$A$10,0),MATCH(Weights!$H$4,Resources!$B$1:$F$1,0)))+Weights!$I$4*IF(Weights!$J$4=0,$E9,INDEX(Resources!$B$2:$F$10,MATCH(CHOOSE(Weights!$J$4,$B9,$C9,$D9),Resources!$A$2:$A$10,0),MATCH(Weights!$K$4,Resources!$B$1:$F$1,0))))/10 -> 40.183333 | N9: =IF(M9<40,"Poor",IF(M9<55,"Basic",IF(M9<70,"Solid",IF(M9<85,"Strong",IF(M9<95,"Excellent","Exceptional"))))) -> Basic | O9: =MIN(100,MAX(G9,J9,M9)*(1+0.05*3)) -> 72.258333 | P9: =IF(O9<40,"Poor",IF(O9<55,"Basic",IF(O9<70,"Solid",IF(O9<85,"Strong",IF(O9<95,"Excellent","Exceptional"))))) -> Strong
A10: Basic Drill Head | B10: Keth Iron | C10: Sorrel Vein Copper | D10: Glimmerfall Shard | E10: =AVERAGE(INDEX(Resources!$B$2:$F$10,MATCH($B10,Resources!$A$2:$A$10,0),1),INDEX(Resources!$B$2:$F$10,MATCH($C10,Resources!$A$2:$A$10,0),1),INDEX(Resources!$B$2:$F$10,MATCH($D10,Resources!$A$2:$A$10,0),1)) -> 626.66667 | F10: Extraction Rate | G10: =(Weights!$C$2*IF(Weights!$D$2=0,$E10,INDEX(Resources!$B$2:$F$10,MATCH(CHOOSE(Weights!$D$2,$B10,$C10,$D10),Resources!$A$2:$A$10,0),MATCH(Weights!$E$2,Resources!$B$1:$F$1,0)))+Weights!$F$2*IF(Weights!$G$2=0,$E10,INDEX(Resources!$B$2:$F$10,MATCH(CHOOSE(Weights!$G$2,$B10,$C10,$D10),Resources!$A$2:$A$10,0),MATCH(Weights!$H$2,Resources!$B$1:$F$1,0)))+Weights!$I$2*IF(Weights!$J$2=0,$E10,INDEX(Resources!$B$2:$F$10,MATCH(CHOOSE(Weights!$J$2,$B10,$C10,$D10),Resources!$A$2:$A$10,0),MATCH(Weights!$K$2,Resources!$B$1:$F$1,0))))/10 -> 64.233333 | H10: =IF(G10<40,"Poor",IF(G10<55,"Basic",IF(G10<70,"Solid",IF(G10<85,"Strong",IF(G10<95,"Excellent","Exceptional"))))) -> Solid | I10: Depth Access | J10: =(Weights!$C$3*IF(Weights!$D$3=0,$E10,INDEX(Resources!$B$2:$F$10,MATCH(CHOOSE(Weights!$D$3,$B10,$C10,$D10),Resources!$A$2:$A$10,0),MATCH(Weights!$E$3,Resources!$B$1:$F$1,0)))+Weights!$F$3*IF(Weights!$G$3=0,$E10,INDEX(Resources!$B$2:$F$10,MATCH(CHOOSE(Weights!$G$3,$B10,$C10,$D10),Resources!$A$2:$A$10,0),MATCH(Weights!$H$3,Resources!$B$1:$F$1,0)))+Weights!$I$3*IF(Weights!$J$3=0,$E10,INDEX(Resources!$B$2:$F$10,MATCH(CHOOSE(Weights!$J$3,$B10,$C10,$D10),Resources!$A$2:$A$10,0),MATCH(Weights!$K$3,Resources!$B$1:$F$1,0))))/10 -> 64.233333 | K10: =IF(J10<40,"Poor",IF(J10<55,"Basic",IF(J10<70,"Solid",IF(J10<85,"Strong",IF(J10<95,"Excellent","Exceptional"))))) -> Solid | L10: Wear Control | M10: =(Weights!$C$4*IF(Weights!$D$4=0,$E10,INDEX(Resources!$B$2:$F$10,MATCH(CHOOSE(Weights!$D$4,$B10,$C10,$D10),Resources!$A$2:$A$10,0),MATCH(Weights!$E$4,Resources!$B$1:$F$1,0)))+Weights!$F$4*IF(Weights!$G$4=0,$E10,INDEX(Resources!$B$2:$F$10,MATCH(CHOOSE(Weights!$G$4,$B10,$C10,$D10),Resources!$A$2:$A$10,0),MATCH(Weights!$H$4,Resources!$B$1:$F$1,0)))+Weights!$I$4*IF(Weights!$J$4=0,$E10,INDEX(Resources!$B$2:$F$10,MATCH(CHOOSE(Weights!$J$4,$B10,$C10,$D10),Resources!$A$2:$A$10,0),MATCH(Weights!$K$4,Resources!$B$1:$F$1,0))))/10 -> 60.933333 | N10: =IF(M10<40,"Poor",IF(M10<55,"Basic",IF(M10<70,"Solid",IF(M10<85,"Strong",IF(M10<95,"Excellent","Exceptional"))))) -> Solid | O10: =MIN(100,MAX(G10,J10,M10)*(1+0.05*3)) -> 73.868333 | P10: =IF(O10<40,"Poor",IF(O10<55,"Basic",IF(O10<70,"Solid",IF(O10<85,"Strong",IF(O10<95,"Excellent","Exceptional"))))) -> Strong
A11: Basic Drill Head | B11: Asterion Frame Alloy | C11: Red Mesa Conductive Slag | D11: Pale Ember Crystal | E11: =AVERAGE(INDEX(Resources!$B$2:$F$10,MATCH($B11,Resources!$A$2:$A$10,0),1),INDEX(Resources!$B$2:$F$10,MATCH($C11,Resources!$A$2:$A$10,0),1),INDEX(Resources!$B$2:$F$10,MATCH($D11,Resources!$A$2:$A$10,0),1)) -> 570 | F11: Extraction Rate | G11: =(Weights!$C$2*IF(Weights!$D$2=0,$E11,INDEX(Resources!$B$2:$F$10,MATCH(CHOOSE(Weights!$D$2,$B11,$C11,$D11),Resources!$A$2:$A$10,0),MATCH(Weights!$E$2,Resources!$B$1:$F$1,0)))+Weights!$F$2*IF(Weights!$G$2=0,$E11,INDEX(Resources!$B$2:$F$10,MATCH(CHOOSE(Weights!$G$2,$B11,$C11,$D11),Resources!$A$2:$A$10,0),MATCH(Weights!$H$2,Resources!$B$1:$F$1,0)))+Weights!$I$2*IF(Weights!$J$2=0,$E11,INDEX(Resources!$B$2:$F$10,MATCH(CHOOSE(Weights!$J$2,$B11,$C11,$D11),Resources!$A$2:$A$10,0),MATCH(Weights!$K$2,Resources!$B$1:$F$1,0))))/10 -> 72.2 | H11: =IF(G11<40,"Poor",IF(G11<55,"Basic",IF(G11<70,"Solid",IF(G11<85,"Strong",IF(G11<95,"Excellent","Exceptional"))))) -> Strong | I11: Depth Access | J11: =(Weights!$C$3*IF(Weights!$D$3=0,$E11,INDEX(Resources!$B$2:$F$10,MATCH(CHOOSE(Weights!$D$3,$B11,$C11,$D11),Resources!$A$2:$A$10,0),MATCH(Weights!$E$3,Resources!$B$1:$F$1,0)))+Weights!$F$3*IF(Weights!$G$3=0,$E11,INDEX(Resources!$B$2:$F$10,MATCH(CHOOSE(Weights!$G$3,$B11,$C11,$D11),Resources!$A$2:$A$10,0),MATCH(Weights!$H$3,Resources!$B$1:$F$1,0)))+Weights!$I$3*IF(Weights!$J$3=0,$E11,INDEX(Resources!$B$2:$F$10,MATCH(CHOOSE(Weights!$J$3,$B11,$C11,$D11),Resources!$A$2:$A$10,0),MATCH(Weights!$K$3,Resources!$B$1:$F$1,0))))/10 -> 80.3 | K11: =IF(J11<40,"Poor",IF(J11<55,"Basic",IF(J11<70,"Solid",IF(J11<85,"Strong",IF(J11<95,"Excellent","Exceptional"))))) -> Strong | L11: Wear Control | M11: =(Weights!$C$4*IF(Weights!$D$4=0,$E11,INDEX(Resources!$B$2:$F$10,MATCH(CHOOSE(Weights!$D$4,$B11,$C11,$D11),Resources!$A$2:$A$10,0),MATCH(Weights!$E$4,Resources!$B$1:$F$1,0)))+Weights!$F$4*IF(Weights!$G$4=0,$E11,INDEX(Resources!$B$2:$F$10,MATCH(CHOOSE(Weights!$G$4,$B11,$C11,$D11),Resources!$A$2:$A$10,0),MATCH(Weights!$H$4,Resources!$B$1:$F$1,0)))+Weights!$I$4*IF(Weights!$J$4=0,$E11,INDEX(Resources!$B$2:$F$10,MATCH(CHOOSE(Weights!$J$4,$B11,$C11,$D11),Resources!$A$2:$A$10,0),MATCH(Weights!$K$4,Resources!$B$1:$F$1,0))))/10 -> 77.6 | N11: =IF(M11<40,"Poor",IF(M11<55,"Basic",IF(M11<70,"Solid",IF(M11<85,"Strong",IF(M11<95,"Excellent","Exceptional"))))) -> Strong | O11: =MIN(100,MAX(G11,J11,M11)*(1+0.05*3)) -> 92.345 | P11: =IF(O11<40,"Poor",IF(O11<55,"Basic",IF(O11<70,"Solid",IF(O11<85,"Strong",IF(O11<95,"Excellent","Exceptional"))))) -> Excellent
A12: Basic Drill Head | B12: Asterion Frame Alloy | C12: Red Mesa Conductive Slag | D12: Thornwake Crystal | E12: =AVERAGE(INDEX(Resources!$B$2:$F$10,MATCH($B12,Resources!$A$2:$A$10,0),1),INDEX(Resources!$B$2:$F$10,MATCH($C12,Resources!$A$2:$A$10,0),1),INDEX(Resources!$B$2:$F$10,MATCH($D12,Resources!$A$2:$A$10,0),1)) -> 540 | F12: Extraction Rate | G12: =(Weights!$C$2*IF(Weights!$D$2=0,$E12,INDEX(Resources!$B$2:$F$10,MATCH(CHOOSE(Weights!$D$2,$B12,$C12,$D12),Resources!$A$2:$A$10,0),MATCH(Weights!$E$2,Resources!$B$1:$F$1,0)))+Weights!$F$2*IF(Weights!$G$2=0,$E12,INDEX(Resources!$B$2:$F$10,MATCH(CHOOSE(Weights!$G$2,$B12,$C12,$D12),Resources!$A$2:$A$10,0),MATCH(Weights!$H$2,Resources!$B$1:$F$1,0)))+Weights!$I$2*IF(Weights!$J$2=0,$E12,INDEX(Resources!$B$2:$F$10,MATCH(CHOOSE(Weights!$J$2,$B12,$C12,$D12),Resources!$A$2:$A$10,0),MATCH(Weights!$K$2,Resources!$B$1:$F$1,0))))/10 -> 71.6 | H12: =IF(G12<40,"Poor",IF(G12<55,"Basic",IF(G12<70,"Solid",IF(G12<85,"Strong",IF(G12<95,"Excellent","Exceptional"))))) -> Strong | I12: Depth Access | J12: =(Weights!$C$3*IF(Weights!$D$3=0,$E12,INDEX(Resources!$B$2:$F$10,MATCH(CHOOSE(Weights!$D$3,$B12,$C12,$D12),Resources!$A$2:$A$10,0),MATCH(Weights!$E$3,Resources!$B$1:$F$1,0)))+Weights!$F$3*IF(Weights!$G$3=0,$E12,INDEX(Resources!$B$2:$F$10,MATCH(CHOOSE(Weights!$G$3,$B12,$C12,$D12),Resources!$A$2:$A$10,0),MATCH(Weights!$H$3,Resources!$B$1:$F$1,0)))+Weights!$I$3*IF(Weights!$J$3=0,$E12,INDEX(Resources!$B$2:$F$10,MATCH(CHOOSE(Weights!$J$3,$B12,$C12,$D12),Resources!$A$2:$A$10,0),MATCH(Weights!$K$3,Resources!$B$1:$F$1,0))))/10 -> 59.6 | K12: =IF(J12<40,"Poor",IF(J12<55,"Basic",IF(J12<70,"Solid",IF(J12<85,"Strong",IF(J12<95,"Excellent","Exceptional"))))) -> Solid | L12: Wear Control | M12: =(Weights!$C$4*IF(Weights!$D$4=0,$E12,INDEX(Resources!$B$2:$F$10,MATCH(CHOOSE(Weights!$D$4,$B12,$C12,$D12),Resources!$A$2:$A$10,0),MATCH(Weights!$E$4,Resources!$B$1:$F$1,0)))+Weights!$F$4*IF(Weights!$G$4=0,$E12,INDEX(Resources!$B$2:$F$10,MATCH(CHOOSE(Weights!$G$4,$B12,$C12,$D12),Resources!$A$2:$A$10,0),MATCH(Weights!$H$4,Resources!$B$1:$F$1,0)))+Weights!$I$4*IF(Weights!$J$4=0,$E12,INDEX(Resources!$B$2:$F$10,MATCH(CHOOSE(Weights!$J$4,$B12,$C12,$D12),Resources!$A$2:$A$10,0),MATCH(Weights!$K$4,Resources!$B$1:$F$1,0))))/10 -> 46.85 | N12: =IF(M12<40,"Poor",IF(M12<55,"Basic",IF(M12<70,"Solid",IF(M12<85,"Strong",IF(M12<95,"Excellent","Exceptional"))))) -> Basic | O12: =MIN(100,MAX(G12,J12,M12)*(1+0.05*3)) -> 82.34 | P12: =IF(O12<40,"Poor",IF(O12<55,"Basic",IF(O12<70,"Solid",IF(O12<85,"Strong",IF(O12<95,"Excellent","Exceptional"))))) -> Strong
A13: Basic Drill Head | B13: Asterion Frame Alloy | C13: Red Mesa Conductive Slag | D13: Glimmerfall Shard | E13: =AVERAGE(INDEX(Resources!$B$2:$F$10,MATCH($B13,Resources!$A$2:$A$10,0),1),INDEX(Resources!$B$2:$F$10,MATCH($C13,Resources!$A$2:$A$10,0),1),INDEX(Resources!$B$2:$F$10,MATCH($D13,Resources!$A$2:$A$10,0),1)) -> 610 | F13: Extraction Rate | G13: =(Weights!$C$2*IF(Weights!$D$2=0,$E13,INDEX(Resources!$B$2:$F$10,MATCH(CHOOSE(Weights!$D$2,$B13,$C13,$D13),Resources!$A$2:$A$10,0),MATCH(Weights!$E$2,Resources!$B$1:$F$1,0)))+Weights!$F$2*IF(Weights!$G$2=0,$E13,INDEX(Resources!$B$2:$F$10,MATCH(CHOOSE(Weights!$G$2,$B13,$C13,$D13),Resources!$A$2:$A$10,0),MATCH(Weights!$H$2,Resources!$B$1:$F$1,0)))+Weights!$I$2*IF(Weights!$J$2=0,$E13,INDEX(Resources!$B$2:$F$10,MATCH(CHOOSE(Weights!$J$2,$B13,$C13,$D13),Resources!$A$2:$A$10,0),MATCH(Weights!$K$2,Resources!$B$1:$F$1,0))))/10 -> 73 | H13: =IF(G13<40,"Poor",IF(G13<55,"Basic",IF(G13<70,"Solid",IF(G13<85,"Strong",IF(G13<95,"Excellent","Exceptional"))))) -> Strong | I13: Depth Access | J13: =(Weights!$C$3*IF(Weights!$D$3=0,$E13,INDEX(Resources!$B$2:$F$10,MATCH(CHOOSE(Weights!$D$3,$B13,$C13,$D13),Resources!$A$2:$A$10,0),MATCH(Weights!$E$3,Resources!$B$1:$F$1,0)))+Weights!$F$3*IF(Weights!$G$3=0,$E13,INDEX(Resources!$B$2:$F$10,MATCH(CHOOSE(Weights!$G$3,$B13,$C13,$D13),Resources!$A$2:$A$10,0),MATCH(Weights!$H$3,Resources!$B$1:$F$1,0)))+Weights!$I$3*IF(Weights!$J$3=0,$E13,INDEX(Resources!$B$2:$F$10,MATCH(CHOOSE(Weights!$J$3,$B13,$C13,$D13),Resources!$A$2:$A$10,0),MATCH(Weights!$K$3,Resources!$B$1:$F$1,0))))/10 -> 73.9 | K13: =IF(J13<40,"Poor",IF(J13<55,"Basic",IF(J13<70,"Solid",IF(J13<85,"Strong",IF(J13<95,"Excellent","Exceptional"))))) -> Strong | L13: Wear Control | M13: =(Weights!$C$4*IF(Weights!$D$4=0,$E13,INDEX(Resources!$B$2:$F$10,MATCH(CHOOSE(Weights!$D$4,$B13,$C13,$D13),Resources!$A$2:$A$10,0),MATCH(Weights!$E$4,Resources!$B$1:$F$1,0)))+Weights!$F$4*IF(Weights!$G$4=0,$E13,INDEX(Resources!$B$2:$F$10,MATCH(CHOOSE(Weights!$G$4,$B13,$C13,$D13),Resources!$A$2:$A$10,0),MATCH(Weights!$H$4,Resources!$B$1:$F$1,0)))+Weights!$I$4*IF(Weights!$J$4=0,$E13,INDEX(Resources!$B$2:$F$10,MATCH(CHOOSE(Weights!$J$4,$B13,$C13,$D13),Resources!$A$2:$A$10,0),MATCH(Weights!$K$4,Resources!$B$1:$F$1,0))))/10 -> 67.6 | N13: =IF(M13<40,"Poor",IF(M13<55,"Basic",IF(M13<70,"Solid",IF(M13<85,"Strong",IF(M13<95,"Excellent","Exceptional"))))) -> Solid | O13: =MIN(100,MAX(G13,J13,M13)*(1+0.05*3)) -> 84.985 | P13: =IF(O13<40,"Poor",IF(O13<55,"Basic",IF(O13<70,"Solid",IF(O13<85,"Strong",IF(O13<95,"Excellent","Exceptional"))))) -> Strong
... A28: Basic Drill Head | B28: Bendrel Ridge Alloy | C28: Sorrel Vein Copper | D28: Glimmerfall Shard | E28: =AVERAGE(INDEX(Resources!$B$2:$F$10,MATCH($B28,Resources!$A$2:$A$10,0),1),INDEX(Resources!$B$2:$F$10,MATCH($C28,Resources!$A$2:$A$10,0),1),INDEX(Resources!$B$2:$F$10,MATCH($D28,Resources!$A$2:$A$10,0),1)) -> 656.66667 | F28: Extraction Rate | G28: =(Weights!$C$2*IF(Weights!$D$2=0,$E28,INDEX(Resources!$B$2:$F$10,MATCH(CHOOSE(Weights!$D$2,$B28,$C28,$D28),Resources!$A$2:$A$10,0),MATCH(Weights!$E$2,Resources!$B$1:$F$1,0)))+Weights!$F$2*IF(Weights!$G$2=0,$E28,INDEX(Resources!$B$2:$F$10,MATCH(CHOOSE(Weights!$G$2,$B28,$C28,$D28),Resources!$A$2:$A$10,0),MATCH(Weights!$H$2,Resources!$B$1:$F$1,0)))+Weights!$I$2*IF(Weights!$J$2=0,$E28,INDEX(Resources!$B$2:$F$10,MATCH(CHOOSE(Weights!$J$2,$B28,$C28,$D28),Resources!$A$2:$A$10,0),MATCH(Weights!$K$2,Resources!$B$1:$F$1,0))))/10 -> 53.833333 | H28: =IF(G28<40,"Poor",IF(G28<55,"Basic",IF(G28<70,"Solid",IF(G28<85,"Strong",IF(G28<95,"Excellent","Exceptional"))))) -> Basic | I28: Depth Access | J28: =(Weights!$C$3*IF(Weights!$D$3=0,$E28,INDEX(Resources!$B$2:$F$10,MATCH(CHOOSE(Weights!$D$3,$B28,$C28,$D28),Resources!$A$2:$A$10,0),MATCH(Weights!$E$3,Resources!$B$1:$F$1,0)))+Weights!$F$3*IF(Weights!$G$3=0,$E28,INDEX(Resources!$B$2:$F$10,MATCH(CHOOSE(Weights!$G$3,$B28,$C28,$D28),Resources!$A$2:$A$10,0),MATCH(Weights!$H$3,Resources!$B$1:$F$1,0)))+Weights!$I$3*IF(Weights!$J$3=0,$E28,INDEX(Resources!$B$2:$F$10,MATCH(CHOOSE(Weights!$J$3,$B28,$C28,$D28),Resources!$A$2:$A$10,0),MATCH(Weights!$K$3,Resources!$B$1:$F$1,0))))/10 -> 53.833333 | K28: =IF(J28<40,"Poor",IF(J28<55,"Basic",IF(J28<70,"Solid",IF(J28<85,"Strong",IF(J28<95,"Excellent","Exceptional"))))) -> Basic | L28: Wear Control | M28: =(Weights!$C$4*IF(Weights!$D$4=0,$E28,INDEX(Resources!$B$2:$F$10,MATCH(CHOOSE(Weights!$D$4,$B28,$C28,$D28),Resources!$A$2:$A$10,0),MATCH(Weights!$E$4,Resources!$B$1:$F$1,0)))+Weights!$F$4*IF(Weights!$G$4=0,$E28,INDEX(Resources!$B$2:$F$10,MATCH(CHOOSE(Weights!$G$4,$B28,$C28,$D28),Resources!$A$2:$A$10,0),MATCH(Weights!$H$4,Resources!$B$1:$F$1,0)))+Weights!$I$4*IF(Weights!$J$4=0,$E28,INDEX(Resources!$B$2:$F$10,MATCH(CHOOSE(Weights!$J$4,$B28,$C28,$D28),Resources!$A$2:$A$10,0),MATCH(Weights!$K$4,Resources!$B$1:$F$1,0))))/10 -> 72.733333 | N28: =IF(M28<40,"Poor",IF(M28<55,"Basic",IF(M28<70,"Solid",IF(M28<85,"Strong",IF(M28<95,"Excellent","Exceptional"))))) -> Strong | O28: =MIN(100,MAX(G28,J28,M28)*(1+0.05*3)) -> 83.643333 | P28: =IF(O28<40,"Poor",IF(O28<55,"Basic",IF(O28<70,"Solid",IF(O28<85,"Strong",IF(O28<95,"Excellent","Exceptional"))))) -> Strong
A29: Efficient Pump | B29: Red Mesa Conductive Slag | C29: Keth Iron | D29: Pale Ember Crystal | E29: =AVERAGE(INDEX(Resources!$B$2:$F$10,MATCH($B29,Resources!$A$2:$A$10,0),1),INDEX(Resources!$B$2:$F$10,MATCH($C29,Resources!$A$2:$A$10,0),1),INDEX(Resources!$B$2:$F$10,MATCH($D29,Resources!$A$2:$A$10,0),1)) -> 513.33333 | F29: Recovery Efficiency | G29: =(Weights!$C$5*IF(Weights!$D$5=0,$E29,INDEX(Resources!$B$2:$F$10,MATCH(CHOOSE(Weights!$D$5,$B29,$C29,$D29),Resources!$A$2:$A$10,0),MATCH(Weights!$E$5,Resources!$B$1:$F$1,0)))+Weights!$F$5*IF(Weights!$G$5=0,$E29,INDEX(Resources!$B$2:$F$10,MATCH(CHOOSE(Weights!$G$5,$B29,$C29,$D29),Resources!$A$2:$A$10,0),MATCH(Weights!$H$5,Resources!$B$1:$F$1,0)))+Weights!$I$5*IF(Weights!$J$5=0,$E29,INDEX(Resources!$B$2:$F$10,MATCH(CHOOSE(Weights!$J$5,$B29,$C29,$D29),Resources!$A$2:$A$10,0),MATCH(Weights!$K$5,Resources!$B$1:$F$1,0))))/10 -> 57.316667 | H29: =IF(G29<40,"Poor",IF(G29<55,"Basic",IF(G29<70,"Solid",IF(G29<85,"Strong",IF(G29<95,"Excellent","Exceptional"))))) -> Solid | I29: Clog Resistance | J29: =(Weights!$C$6*IF(Weights!$D$6=0,$E29,INDEX(Resources!$B$2:$F$10,MATCH(CHOOSE(Weights!$D$6,$B29,$C29,$D29),Resources!$A$2:$A$10,0),MATCH(Weights!$E$6,Resources!$B$1:$F$1,0)))+Weights!$F$6*IF(Weights!$G$6=0,$E29,INDEX(Resources!$B$2:$F$10,MATCH(CHOOSE(Weights!$G$6,$B29,$C29,$D29),Resources!$A$2:$A$10,0),MATCH(Weights!$H$6,Resources!$B$1:$F$1,0)))+Weights!$I$6*IF(Weights!$J$6=0,$E29,INDEX(Resources!$B$2:$F$10,MATCH(CHOOSE(Weights!$J$6,$B29,$C29,$D29),Resources!$A$2:$A$10,0),MATCH(Weights!$K$6,Resources!$B$1:$F$1,0))))/10 -> 57.533333 | K29: =IF(J29<40,"Poor",IF(J29<55,"Basic",IF(J29<70,"Solid",IF(J29<85,"Strong",IF(J29<95,"Excellent","Exceptional"))))) -> Solid | L29: Field Stability | M29: =(Weights!$C$7*IF(Weights!$D$7=0,$E29,INDEX(Resources!$B$2:$F$10,MATCH(CHOOSE(Weights!$D$7,$B29,$C29,$D29),Resources!$A$2:$A$10,0),MATCH(Weights!$E$7,Resources!$B$1:$F$1,0)))+Weights!$F$7*IF(Weights!$G$7=0,$E29,INDEX(Resources!$B$2:$F$10,MATCH(CHOOSE(Weights!$G$7,$B29,$C29,$D29),Resources!$A$2:$A$10,0),MATCH(Weights!$H$7,Resources!$B$1:$F$1,0)))+Weights!$I$7*IF(Weights!$J$7=0,$E29,INDEX(Resources!$B$2:$F$10,MATCH(CHOOSE(Weights!$J$7,$B29,$C29,$D29),Resources!$A$2:$A$10,0),MATCH(Weights!$K$7,Resources!$B$1:$F$1,0))))/10 -> 63.516667 | N29: =IF(M29<40,"Poor",IF(M29<55,"Basic",IF(M29<70,"Solid",IF(M29<85,"Strong",IF(M29<95,"Excellent","Exceptional"))))) -> Solid | O29: =MIN(100,MAX(G29,J29,M29)*(1+0.05*3)) -> 73.044167 | P29: =IF(O29<40,"Poor",IF(O29<55,"Basic",IF(O29<70,"Solid",IF(O29<85,"Strong",IF(O29<95,"Excellent","Exceptional"))))) -> Strong
A30: Efficient Pump | B30: Red Mesa Conductive Slag | C30: Keth Iron | D30: Thornwake Crystal | E30: =AVERAGE(INDEX(Resources!$B$2:$F$10,MATCH($B30,Resources!$A$2:$A$10,0),1),INDEX(Resources!$B$2:$F$10,MATCH($C30,Resources!$A$2:$A$10,0),1),INDEX(Resources!$B$2:$F$10,MATCH($D30,Resources!$A$2:$A$10,0),1)) -> 483.33333 | F30: Recovery Efficiency | G30: =(Weights!$C$5*IF(Weights!$D$5=0,$E30,INDEX(Resources!$B$2:$F$10,MATCH(CHOOSE(Weights!$D$5,$B30,$C30,$D30),Resources!$A$2:$A$10,0),MATCH(Weights!$E$5,Resources!$B$1:$F$1,0)))+Weights!$F$5*IF(Weights!$G$5=0,$E30,INDEX(Resources!$B$2:$F$10,MATCH(CHOOSE(Weights!$G$5,$B30,$C30,$D30),Resources!$A$2:$A$10,0),MATCH(Weights!$H$5,Resources!$B$1:$F$1,0)))+Weights!$I$5*IF(Weights!$J$5=0,$E30,INDEX(Resources!$B$2:$F$10,MATCH(CHOOSE(Weights!$J$5,$B30,$C30,$D30),Resources!$A$2:$A$10,0),MATCH(Weights!$K$5,Resources!$B$1:$F$1,0))))/10 -> 56.716667 | H30: =IF(G30<40,"Poor",IF(G30<55,"Basic",IF(G30<70,"Solid",IF(G30<85,"Strong",IF(G30<95,"Excellent","Exceptional"))))) -> Solid | I30: Clog Resistance | J30: =(Weights!$C$6*IF(Weights!$D$6=0,$E30,INDEX(Resources!$B$2:$F$10,MATCH(CHOOSE(Weights!$D$6,$B30,$C30,$D30),Resources!$A$2:$A$10,0),MATCH(Weights!$E$6,Resources!$B$1:$F$1,0)))+Weights!$F$6*IF(Weights!$G$6=0,$E30,INDEX(Resources!$B$2:$F$10,MATCH(CHOOSE(Weights!$G$6,$B30,$C30,$D30),Resources!$A$2:$A$10,0),MATCH(Weights!$H$6,Resources!$B$1:$F$1,0)))+Weights!$I$6*IF(Weights!$J$6=0,$E30,INDEX(Resources!$B$2:$F$10,MATCH(CHOOSE(Weights!$J$6,$B30,$C30,$D30),Resources!$A$2:$A$10,0),MATCH(Weights!$K$6,Resources!$B$1:$F$1,0))))/10 -> 56.783333 | K30: =IF(J30<40,"Poor",IF(J30<55,"Basic",IF(J30<70,"Solid",IF(J30<85,"Strong",IF(J30<95,"Excellent","Exceptional"))))) -> Solid | L30: Field Stability | M30: =(Weights!$C$7*IF(Weights!$D$7=0,$E30,INDEX(Resources!$B$2:$F$10,MATCH(CHOOSE(Weights!$D$7,$B30,$C30,$D30),Resources!$A$2:$A$10,0),MATCH(Weights!$E$7,Resources!$B$1:$F$1,0)))+Weights!$F$7*IF(Weights!$G$7=0,$E30,INDEX(Resources!$B$2:$F$10,MATCH(CHOOSE(Weights!$G$7,$B30,$C30,$D30),Resources!$A$2:$A$10,0),MATCH(Weights!$H$7,Resources!$B$1:$F$1,0)))+Weights!$I$7*IF(Weights!$J$7=0,$E30,INDEX(Resources!$B$2:$F$10,MATCH(CHOOSE(Weights!$J$7,$B30,$C30,$D30),Resources!$A$2:$A$10,0),MATCH(Weights!$K$7,Resources!$B$1:$F$1,0))))/10 -> 32.766667 | N30: =IF(M30<40,"Poor",IF(M30<55,"Basic",IF(M30<70,"Solid",IF(M30<85,"Strong",IF(M30<95,"Excellent","Exceptional"))))) -> Poor | O30: =MIN(100,MAX(G30,J30,M30)*(1+0.05*3)) -> 65.300833 | P30: =IF(O30<40,"Poor",IF(O30<55,"Basic",IF(O30<70,"Solid",IF(O30<85,"Strong",IF(O30<95,"Excellent","Exceptional"))))) -> Solid
A31: Efficient Pump | B31: Red Mesa Conductive Slag | C31: Keth Iron | D31: Glimmerfall Shard | E31: =AVERAGE(INDEX(Resources!$B$2:$F$10,MATCH($B31,Resources!$A$2:$A$10,0),1),INDEX(Resources!$B$2:$F$10,MATCH($C31,Resources!$A$2:$A$10,0),1),INDEX(Resources!$B$2:$F$10,MATCH($D31,Resources!$A$2:$A$10,0),1)) -> 553.33333 | F31: Recovery Efficiency | G31: =(Weights!$C$5*IF(Weights!$D$5=0,$E31,INDEX(Resources!$B$2:$F$10,MATCH(CHOOSE(Weights!$D$5,$B31,$C31,$D31),Resources!$A$2:$A$10,0),MATCH(Weights!$E$5,Resources!$B$1:$F$1,0)))+Weights!$F$5*IF(Weights!$G$5=0,$E31,INDEX(Resources!$B$2:$F$10,MATCH(CHOOSE(Weights!$G$5,$B31,$C31,$D31),Resources!$A$2:$A$10,0),MATCH(Weights!$H$5,Resources!$B$1:$F$1,0)))+Weights!$I$5*IF(Weights!$J$5=0,$E31,INDEX(Resources!$B$2:$F$10,MATCH(CHOOSE(Weights!$J$5,$B31,$C31,$D31),Resources!$A$2:$A$10,0),MATCH(Weights!$K$5,Resources!$B$1:$F$1,0))))/10 -> 58.116667 | H31: =IF(G31<40,"Poor",IF(G31<55,"Basic",IF(G31<70,"Solid",IF(G31<85,"Strong",IF(G31<95,"Excellent","Exceptional"))))) -> Solid | I31: Clog Resistance | J31: =(Weights!$C$6*IF(Weights!$D$6=0,$E31,INDEX(Resources!$B$2:$F$10,MATCH(CHOOSE(Weights!$D$6,$B31,$C31,$D31),Resources!$A$2:$A$10,0),MATCH(Weights!$E$6,Resources!$B$1:$F$1,0)))+Weights!$F$6*IF(Weights!$G$6=0,$E31,INDEX(Resources!$B$2:$F$10,MATCH(CHOOSE(Weights!$G$6,$B31,$C31,$D31),Resources!$A$2:$A$10,0),MATCH(Weights!$H$6,Resources!$B$1:$F$1,0)))+Weights!$I$6*IF(Weights!$J$6=0,$E31,INDEX(Resources!$B$2:$F$10,MATCH(CHOOSE(Weights!$J$6,$B31,$C31,$D31),Resources!$A$2:$A$10,0),MATCH(Weights!$K$6,Resources!$B$1:$F$1,0))))/10 -> 58.533333 | K31: =IF(J31<40,"Poor",IF(J31<55,"Basic",IF(J31<70,"Solid",IF(J31<85,"Strong",IF(J31<95,"Excellent","Exceptional"))))) -> Solid | L31: Field Stability | M31: =(Weights!$C$7*IF(Weights!$D$7=0,$E31,INDEX(Resources!$B$2:$F$10,MATCH(CHOOSE(Weights!$D$7,$B31,$C31,$D31),Resources!$A$2:$A$10,0),MATCH(Weights!$E$7,Resources!$B$1:$F$1,0)))+Weights!$F$7*IF(Weights!$G$7=0,$E31,INDEX(Resources!$B$2:$F$10,MATCH(CHOOSE(Weights!$G$7,$B31,$C31,$D31),Resources!$A$2:$A$10,0),MATCH(Weights!$H$7,Resources!$B$1:$F$1,0)))+Weights!$I$7*IF(Weights!$J$7=0,$E31,INDEX(Resources!$B$2:$F$10,MATCH(CHOOSE(Weights!$J$7,$B31,$C31,$D31),Resources!$A$2:$A$10,0),MATCH(Weights!$K$7,Resources!$B$1:$F$1,0))))/10 -> 53.516667 | N31: =IF(M31<40,"Poor",IF(M31<55,"Basic",IF(M31<70,"Solid",IF(M31<85,"Strong",IF(M31<95,"Excellent","Exceptional"))))) -> Basic | O31: =MIN(100,MAX(G31,J31,M31)*(1+0.05*3)) -> 67.313333 | P31: =IF(O31<40,"Poor",IF(O31<55,"Basic",IF(O31<70,"Solid",IF(O31<85,"Strong",IF(O31<95,"Excellent","Exceptional"))))) -> Solid
A32: Efficient Pump | B32: Red Mesa Conductive Slag | C32: Asterion Frame Alloy | D32: Pale Ember Crystal | E32: =AVERAGE(INDEX(Resources!$B$2:$F$10,MATCH($B32,Resources!$A$2:$A$10,0),1),INDEX(Resources!$B$2:$F$10,MATCH($C32,Resources!$A$2:$A$10,0),1),INDEX(Resources!$B$2:$F$10,MATCH($D32,Resources!$A$2:$A$10,0),1)) -> 570 | F32: Recovery Efficiency | G32: =(Weights!$C$5*IF(Weights!$D$5=0,$E32,INDEX(Resources!$B$2:$F$10,MATCH(CHOOSE(Weights!$D$5,$B32,$C32,$D32),Resources!$A$2:$A$10,0),MATCH(Weights!$E$5,Resources!$B$1:$F$1,0)))+Weights!$F$5*IF(Weights!$G$5=0,$E32,INDEX(Resources!$B$2:$F$10,MATCH(CHOOSE(Weights!$G$5,$B32,$C32,$D32),Resources!$A$2:$A$10,0),MATCH(Weights!$H$5,Resources!$B$1:$F$1,0)))+Weights!$I$5*IF(Weights!$J$5=0,$E32,INDEX(Resources!$B$2:$F$10,MATCH(CHOOSE(Weights!$J$5,$B32,$C32,$D32),Resources!$A$2:$A$10,0),MATCH(Weights!$K$5,Resources!$B$1:$F$1,0))))/10 -> 65.45 | H32: =IF(G32<40,"Poor",IF(G32<55,"Basic",IF(G32<70,"Solid",IF(G32<85,"Strong",IF(G32<95,"Excellent","Exceptional"))))) -> Solid | I32: Clog Resistance | J32: =(Weights!$C$6*IF(Weights!$D$6=0,$E32,INDEX(Resources!$B$2:$F$10,MATCH(CHOOSE(Weights!$D$6,$B32,$C32,$D32),Resources!$A$2:$A$10,0),MATCH(Weights!$E$6,Resources!$B$1:$F$1,0)))+Weights!$F$6*IF(Weights!$G$6=0,$E32,INDEX(Resources!$B$2:$F$10,MATCH(CHOOSE(Weights!$G$6,$B32,$C32,$D32),Resources!$A$2:$A$10,0),MATCH(Weights!$H$6,Resources!$B$1:$F$1,0)))+Weights!$I$6*IF(Weights!$J$6=0,$E32,INDEX(Resources!$B$2:$F$10,MATCH(CHOOSE(Weights!$J$6,$B32,$C32,$D32),Resources!$A$2:$A$10,0),MATCH(Weights!$K$6,Resources!$B$1:$F$1,0))))/10 -> 73.95 | K32: =IF(J32<40,"Poor",IF(J32<55,"Basic",IF(J32<70,"Solid",IF(J32<85,"Strong",IF(J32<95,"Excellent","Exceptional"))))) -> Strong | L32: Field Stability | M32: =(Weights!$C$7*IF(Weights!$D$7=0,$E32,INDEX(Resources!$B$2:$F$10,MATCH(CHOOSE(Weights!$D$7,$B32,$C32,$D32),Resources!$A$2:$A$10,0),MATCH(Weights!$E$7,Resources!$B$1:$F$1,0)))+Weights!$F$7*IF(Weights!$G$7=0,$E32,INDEX(Resources!$B$2:$F$10,MATCH(CHOOSE(Weights!$G$7,$B32,$C32,$D32),Resources!$A$2:$A$10,0),MATCH(Weights!$H$7,Resources!$B$1:$F$1,0)))+Weights!$I$7*IF(Weights!$J$7=0,$E32,INDEX(Resources!$B$2:$F$10,MATCH(CHOOSE(Weights!$J$7,$B32,$C32,$D32),Resources!$A$2:$A$10,0),MATCH(Weights!$K$7,Resources!$B$1:$F$1,0))))/10 -> 64.65 | N32: =IF(M32<40,"Poor",IF(M32<55,"Basic",IF(M32<70,"Solid",IF(M32<85,"Strong",IF(M32<95,"Excellent","Exceptional"))))) -> Solid | O32: =MIN(100,MAX(G32,J32,M32)*(1+0.05*3)) -> 85.0425 | P32: =IF(O32<40,"Poor",IF(O32<55,"Basic",IF(O32<70,"Solid",IF(O32<85,"Strong",IF(O32<95,"Excellent","Exceptional"))))) -> Excellent
A33: Efficient Pump | B33: Red Mesa Conductive Slag | C33: Asterion Frame Alloy | D33: Thornwake Crystal | E33: =AVERAGE(INDEX(Resources!$B$2:$F$10,MATCH($B33,Resources!$A$2:$A$10,0),1),INDEX(Resources!$B$2:$F$10,MATCH($C33,Resources!$A$2:$A$10,0),1),INDEX(Resources!$B$2:$F$10,MATCH($D33,Resources!$A$2:$A$10,0),1)) -> 540 | F33: Recovery Efficiency | G33: =(Weights!$C$5*IF(Weights!$D$5=0,$E33,INDEX(Resources!$B$2:$F$10,MATCH(CHOOSE(Weights!$D$5,$B33,$C33,$D33),Resources!$A$2:$A$10,0),MATCH(Weights!$E$5,Resources!$B$1:$F$1,0)))+Weights!$F$5*IF(Weights!$G$5=0,$E33,INDEX(Resources!$B$2:$F$10,MATCH(CHOOSE(Weights!$G$5,$B33,$C33,$D33),Resources!$A$2:$A$10,0),MATCH(Weights!$H$5,Resources!$B$1:$F$1,0)))+Weights!$I$5*IF(Weights!$J$5=0,$E33,INDEX(Resources!$B$2:$F$10,MATCH(CHOOSE(Weights!$J$5,$B33,$C33,$D33),Resources!$A$2:$A$10,0),MATCH(Weights!$K$5,Resources!$B$1:$F$1,0))))/10 -> 64.85 | H33: =IF(G33<40,"Poor",IF(G33<55,"Basic",IF(G33<70,"Solid",IF(G33<85,"Strong",IF(G33<95,"Excellent","Exceptional"))))) -> Solid | I33: Clog Resistance | J33: =(Weights!$C$6*IF(Weights!$D$6=0,$E33,INDEX(Resources!$B$2:$F$10,MATCH(CHOOSE(Weights!$D$6,$B33,$C33,$D33),Resources!$A$2:$A$10,0),MATCH(Weights!$E$6,Resources!$B$1:$F$1,0)))+Weights!$F$6*IF(Weights!$G$6=0,$E33,INDEX(Resources!$B$2:$F$10,MATCH(CHOOSE(Weights!$G$6,$B33,$C33,$D33),Resources!$A$2:$A$10,0),MATCH(Weights!$H$6,Resources!$B$1:$F$1,0)))+Weights!$I$6*IF(Weights!$J$6=0,$E33,INDEX(Resources!$B$2:$F$10,MATCH(CHOOSE(Weights!$J$6,$B33,$C33,$D33),Resources!$A$2:$A$10,0),MATCH(Weights!$K$6,Resources!$B$1:$F$1,0))))/10 -> 73.2 | K33: =IF(J33<40,"Poor",IF(J33<55,"Basic",IF(J33<70,"Solid",IF(J33<85,"Strong",IF(J33<95,"Excellent","Exceptional"))))) -> Strong | L33: Field Stability | M33: =(Weights!$C$7*IF(Weights!$D$7=0,$E33,INDEX(Resources!$B$2:$F$10,MATCH(CHOOSE(Weights!$D$7,$B33,$C33,$D33),Resources!$A$2:$A$10,0),MATCH(Weights!$E$7,Resources!$B$1:$F$1,0)))+Weights!$F$7*IF(Weights!$G$7=0,$E33,INDEX(Resources!$B$2:$F$10,MATCH(CHOOSE(Weights!$G$7,$B33,$C33,$D33),Resources!$A$2:$A$10,0),MATCH(Weights!$H$7,Resources!$B$1:$F$1,0)))+Weights!$I$7*IF(Weights!$J$7=0,$E33,INDEX(Resources!$B$2:$F$10,MATCH(CHOOSE(Weights!$J$7,$B33,$C33,$D33),Resources!$A$2:$A$10,0),MATCH(Weights!$K$7,Resources!$B$1:$F$1,0))))/10 -> 33.9 | N33: =IF(M33<40,"Poor",IF(M33<55,"Basic",IF(M33<70,"Solid",IF(M33<85,"Strong",IF(M33<95,"Excellent","Exceptional"))))) -> Poor | O33: =MIN(100,MAX(G33,J33,M33)*(1+0.05*3)) -> 84.18 | P33: =IF(O33<40,"Poor",IF(O33<55,"Basic",IF(O33<70,"Solid",IF(O33<85,"Strong",IF(O33<95,"Excellent","Exceptional"))))) -> Strong
A34: Efficient Pump | B34: Red Mesa Conductive Slag | C34: Asterion Frame Alloy | D34: Glimmerfall Shard | E34: =AVERAGE(INDEX(Resources!$B$2:$F$10,MATCH($B34,Resources!$A$2:$A$10,0),1),INDEX(Resources!$B$2:$F$10,MATCH($C34,Resources!$A$2:$A$10,0),1),INDEX(Resources!$B$2:$F$10,MATCH($D34,Resources!$A$2:$A$10,0),1)) -> 610 | F34: Recovery Efficiency | G34: =(Weights!$C$5*IF(Weights!$D$5=0,$E34,INDEX(Resources!$B$2:$F$10,MATCH(CHOOSE(Weights!$D$5,$B34,$C34,$D34),Resources!$A$2:$A$10,0),MATCH(Weights!$E$5,Resources!$B$1:$F$1,0)))+Weights!$F$5*IF(Weights!$G$5=0,$E34,INDEX(Resources!$B$2:$F$10,MATCH(CHOOSE(Weights!$G$5,$B34,$C34,$D34),Resources!$A$2:$A$10,0),MATCH(Weights!$H$5,Resources!$B$1:$F$1,0)))+Weights!$I$5*IF(Weights!$J$5=0,$E34,INDEX(Resources!$B$2:$F$10,MATCH(CHOOSE(Weights!$J$5,$B34,$C34,$D34),Resources!$A$2:$A$10,0),MATCH(Weights!$K$5,Resources!$B$1:$F$1,0))))/10 -> 66.25 | H34: =IF(G34<40,"Poor",IF(G34<55,"Basic",IF(G34<70,"Solid",IF(G34<85,"Strong",IF(G34<95,"Excellent","Exceptional"))))) -> Solid | I34: Clog Resistance | J34: =(Weights!$C$6*IF(Weights!$D$6=0,$E34,INDEX(Resources!$B$2:$F$10,MATCH(CHOOSE(Weights!$D$6,$B34,$C34,$D34),Resources!$A$2:$A$10,0),MATCH(Weights!$E$6,Resources!$B$1:$F$1,0)))+Weights!$F$6*IF(Weights!$G$6=0,$E34,INDEX(Resources!$B$2:$F$10,MATCH(CHOOSE(Weights!$G$6,$B34,$C34,$D34),Resources!$A$2:$A$10,0),MATCH(Weights!$H$6,Resources!$B$1:$F$1,0)))+Weights!$I$6*IF(Weights!$J$6=0,$E34,INDEX(Resources!$B$2:$F$10,MATCH(CHOOSE(Weights!$J$6,$B34,$C34,$D34),Resources!$A$2:$A$10,0),MATCH(Weights!$K$6,Resources!$B$1:$F$1,0))))/10 -> 74.95 | K34: =IF(J34<40,"Poor",IF(J34<55,"Basic",IF(J34<70,"Solid",IF(J34<85,"Strong",IF(J34<95,"Excellent","Exceptional"))))) -> Strong | L34: Field Stability | M34: =(Weights!$C$7*IF(Weights!$D$7=0,$E34,INDEX(Resources!$B$2:$F$10,MATCH(CHOOSE(Weights!$D$7,$B34,$C34,$D34),Resources!$A$2:$A$10,0),MATCH(Weights!$E$7,Resources!$B$1:$F$1,0)))+Weights!$F$7*IF(Weights!$G$7=0,$E34,INDEX(Resources!$B$2:$F$10,MATCH(CHOOSE(Weights!$G$7,$B34,$C34,$D34),Resources!$A$2:$A$10,0),MATCH(Weights!$H$7,Resources!$B$1:$F$1,0)))+Weights!$I$7*IF(Weights!$J$7=0,$E34,INDEX(Resources!$B$2:$F$10,MATCH(CHOOSE(Weights!$J$7,$B34,$C34,$D34),Resources!$A$2:$A$10,0),MATCH(Weights!$K$7,Resources!$B$1:$F$1,0))))/10 -> 54.65 | N34: =IF(M34<40,"Poor",IF(M34<55,"Basic",IF(M34<70,"Solid",IF(M34<85,"Strong",IF(M34<95,"Excellent","Exceptional"))))) -> Basic | O34: =MIN(100,MAX(G34,J34,M34)*(1+0.05*3)) -> 86.1925 | P34: =IF(O34<40,"Poor",IF(O34<55,"Basic",IF(O34<70,"Solid",IF(O34<85,"Strong",IF(O34<95,"Excellent","Exceptional"))))) -> Excellent
A35: Efficient Pump | B35: Red Mesa Conductive Slag | C35: Bendrel Ridge Alloy | D35: Pale Ember Crystal | E35: =AVERAGE(INDEX(Resources!$B$2:$F$10,MATCH($B35,Resources!$A$2:$A$10,0),1),INDEX(Resources!$B$2:$F$10,MATCH($C35,Resources!$A$2:$A$10,0),1),INDEX(Resources!$B$2:$F$10,MATCH($D35,Resources!$A$2:$A$10,0),1)) -> 543.33333 | F35: Recovery Efficiency | G35: =(Weights!$C$5*IF(Weights!$D$5=0,$E35,INDEX(Resources!$B$2:$F$10,MATCH(CHOOSE(Weights!$D$5,$B35,$C35,$D35),Resources!$A$2:$A$10,0),MATCH(Weights!$E$5,Resources!$B$1:$F$1,0)))+Weights!$F$5*IF(Weights!$G$5=0,$E35,INDEX(Resources!$B$2:$F$10,MATCH(CHOOSE(Weights!$G$5,$B35,$C35,$D35),Resources!$A$2:$A$10,0),MATCH(Weights!$H$5,Resources!$B$1:$F$1,0)))+Weights!$I$5*IF(Weights!$J$5=0,$E35,INDEX(Resources!$B$2:$F$10,MATCH(CHOOSE(Weights!$J$5,$B35,$C35,$D35),Resources!$A$2:$A$10,0),MATCH(Weights!$K$5,Resources!$B$1:$F$1,0))))/10 -> 69.116667 | H35: =IF(G35<40,"Poor",IF(G35<55,"Basic",IF(G35<70,"Solid",IF(G35<85,"Strong",IF(G35<95,"Excellent","Exceptional"))))) -> Solid | I35: Clog Resistance | J35: =(Weights!$C$6*IF(Weights!$D$6=0,$E35,INDEX(Resources!$B$2:$F$10,MATCH(CHOOSE(Weights!$D$6,$B35,$C35,$D35),Resources!$A$2:$A$10,0),MATCH(Weights!$E$6,Resources!$B$1:$F$1,0)))+Weights!$F$6*IF(Weights!$G$6=0,$E35,INDEX(Resources!$B$2:$F$10,MATCH(CHOOSE(Weights!$G$6,$B35,$C35,$D35),Resources!$A$2:$A$10,0),MATCH(Weights!$H$6,Resources!$B$1:$F$1,0)))+Weights!$I$6*IF(Weights!$J$6=0,$E35,INDEX(Resources!$B$2:$F$10,MATCH(CHOOSE(Weights!$J$6,$B35,$C35,$D35),Resources!$A$2:$A$10,0),MATCH(Weights!$K$6,Resources!$B$1:$F$1,0))))/10 -> 66.083333 | K35: =IF(J35<40,"Poor",IF(J35<55,"Basic",IF(J35<70,"Solid",IF(J35<85,"Strong",IF(J35<95,"Excellent","Exceptional"))))) -> Solid | L35: Field Stability | M35: =(Weights!$C$7*IF(Weights!$D$7=0,$E35,INDEX(Resources!$B$2:$F$10,MATCH(CHOOSE(Weights!$D$7,$B35,$C35,$D35),Resources!$A$2:$A$10,0),MATCH(Weights!$E$7,Resources!$B$1:$F$1,0)))+Weights!$F$7*IF(Weights!$G$7=0,$E35,INDEX(Resources!$B$2:$F$10,MATCH(CHOOSE(Weights!$G$7,$B35,$C35,$D35),Resources!$A$2:$A$10,0),MATCH(Weights!$H$7,Resources!$B$1:$F$1,0)))+Weights!$I$7*IF(Weights!$J$7=0,$E35,INDEX(Resources!$B$2:$F$10,MATCH(CHOOSE(Weights!$J$7,$B35,$C35,$D35),Resources!$A$2:$A$10,0),MATCH(Weights!$K$7,Resources!$B$1:$F$1,0))))/10 -> 64.116667 | N35: =IF(M35<40,"Poor",IF(M35<55,"Basic",IF(M35<70,"Solid",IF(M35<85,"Strong",IF(M35<95,"Excellent","Exceptional"))))) -> Solid | O35: =MIN(100,MAX(G35,J35,M35)*(1+0.05*3)) -> 79.484167 | P35: =IF(O35<40,"Poor",IF(O35<55,"Basic",IF(O35<70,"Solid",IF(O35<85,"Strong",IF(O35<95,"Excellent","Exceptional"))))) -> Strong
A36: Efficient Pump | B36: Red Mesa Conductive Slag | C36: Bendrel Ridge Alloy | D36: Thornwake Crystal | E36: =AVERAGE(INDEX(Resources!$B$2:$F$10,MATCH($B36,Resources!$A$2:$A$10,0),1),INDEX(Resources!$B$2:$F$10,MATCH($C36,Resources!$A$2:$A$10,0),1),INDEX(Resources!$B$2:$F$10,MATCH($D36,Resources!$A$2:$A$10,0),1)) -> 513.33333 | F36: Recovery Efficiency | G36: =(Weights!$C$5*IF(Weights!$D$5=0,$E36,INDEX(Resources!$B$2:$F$10,MATCH(CHOOSE(Weights!$D$5,$B36,$C36,$D36),Resources!$A$2:$A$10,0),MATCH(Weights!$E$5,Resources!$B$1:$F$1,0)))+Weights!$F$5*IF(Weights!$G$5=0,$E36,INDEX(Resources!$B$2:$F$10,MATCH(CHOOSE(Weights!$G$5,$B36,$C36,$D36),Resources!$A$2:$A$10,0),MATCH(Weights!$H$5,Resources!$B$1:$F$1,0)))+Weights!$I$5*IF(Weights!$J$5=0,$E36,INDEX(Resources!$B$2:$F$10,MATCH(CHOOSE(Weights!$J$5,$B36,$C36,$D36),Resources!$A$2:$A$10,0),MATCH(Weights!$K$5,Resources!$B$1:$F$1,0))))/10 -> 68.516667 | H36: =IF(G36<40,"Poor",IF(G36<55,"Basic",IF(G36<70,"Solid",IF(G36<85,"Strong",IF(G36<95,"Excellent","Exceptional"))))) -> Solid | I36: Clog Resistance | J36: =(Weights!$C$6*IF(Weights!$D$6=0,$E36,INDEX(Resources!$B$2:$F$10,MATCH(CHOOSE(Weights!$D$6,$B36,$C36,$D36),Resources!$A$2:$A$10,0),MATCH(Weights!$E$6,Resources!$B$1:$F$1,0)))+Weights!$F$6*IF(Weights!$G$6=0,$E36,INDEX(Resources!$B$2:$F$10,MATCH(CHOOSE(Weights!$G$6,$B36,$C36,$D36),Resources!$A$2:$A$10,0),MATCH(Weights!$H$6,Resources!$B$1:$F$1,0)))+Weights!$I$6*IF(Weights!$J$6=0,$E36,INDEX(Resources!$B$2:$F$10,MATCH(CHOOSE(Weights!$J$6,$B36,$C36,$D36),Resources!$A$2:$A$10,0),MATCH(Weights!$K$6,Resources!$B$1:$F$1,0))))/10 -> 65.333333 | K36: =IF(J36<40,"Poor",IF(J36<55,"Basic",IF(J36<70,"Solid",IF(J36<85,"Strong",IF(J36<95,"Excellent","Exceptional"))))) -> Solid | L36: Field Stability | M36: =(Weights!$C$7*IF(Weights!$D$7=0,$E36,INDEX(Resources!$B$2:$F$10,MATCH(CHOOSE(Weights!$D$7,$B36,$C36,$D36),Resources!$A$2:$A$10,0),MATCH(Weights!$E$7,Resources!$B$1:$F$1,0)))+Weights!$F$7*IF(Weights!$G$7=0,$E36,INDEX(Resources!$B$2:$F$10,MATCH(CHOOSE(Weights!$G$7,$B36,$C36,$D36),Resources!$A$2:$A$10,0),MATCH(Weights!$H$7,Resources!$B$1:$F$1,0)))+Weights!$I$7*IF(Weights!$J$7=0,$E36,INDEX(Resources!$B$2:$F$10,MATCH(CHOOSE(Weights!$J$7,$B36,$C36,$D36),Resources!$A$2:$A$10,0),MATCH(Weights!$K$7,Resources!$B$1:$F$1,0))))/10 -> 33.366667 | N36: =IF(M36<40,"Poor",IF(M36<55,"Basic",IF(M36<70,"Solid",IF(M36<85,"Strong",IF(M36<95,"Excellent","Exceptional"))))) -> Poor | O36: =MIN(100,MAX(G36,J36,M36)*(1+0.05*3)) -> 78.794167 | P36: =IF(O36<40,"Poor",IF(O36<55,"Basic",IF(O36<70,"Solid",IF(O36<85,"Strong",IF(O36<95,"Excellent","Exceptional"))))) -> Strong
